---
aliases: 
tags: 
title: 异步.fetch.检测是否请求成功
date created: 星期三, 十一月 23日 2022, 9:51:26 晚上
date modified: 星期三, 十一月 23日 2022, 9:51:34 晚上
---

# 异步.fetch.检测是否请求成功

如果遇到网络故障或服务端的 `CORS` 配置错误时，`fetch()` promise 将会 `reject`，带上一个 `TypeError` 对象。虽然这个情况经常是遇到了权限问题或类似问题——比如 404 不是一个网络故障。想要精确的判断 `fetch()` 是否成功，需要包含 `promise resolved` 的情况，此时再判断 `Response.ok` 是否为 `true`。类似以下代码：

```
fetch('flowers.jpg')
  .then(response => {
    if (!response.ok) {
      throw new Error('Network response was not OK');
    }
    return response.blob();
  })
  .then(myBlob => {
    myImage.src = URL.createObjectURL(myBlob);
  })
  .catch(error => {
    console.error('There has been a problem with your fetch operation:', error);
  });
```
